Workbook

Sheet Summary
A1: Exercise media worklist
A2: Snapshot of data/library.js + complementary.js (26 Sep 2026), custom exercises and logged sessions from Supabase, and batch 2 from library-intake.md.
A3: How to use: on Worklist, click the Search links, paste the chosen URLs into the yellow columns L (video) and M (image/GIF). Done updates itself. Example: the Active hang row already has its video URL in L.
A5: Tier | B5: Exercises | C5: Need video | D5: Need image | E5: Done (both)
A6: 1 In plan / logged | B6: =COUNTIF(Worklist!$A$2:$A$434,A6) -> 65 | C6: =COUNTIFS(Worklist!$A$2:$A$434,A6,Worklist!$L$2:$L$434,"") -> 3 | D6: =COUNTIFS(Worklist!$A$2:$A$434,A6,Worklist!$M$2:$M$434,"") -> 3 | E6: =COUNTIFS(Worklist!$A$2:$A$434,A6,Worklist!$N$2:$N$434,"yes") -> 62
A7: 2 Complementary rotation | B7: =COUNTIF(Worklist!$A$2:$A$434,A7) -> 157 | C7: =COUNTIFS(Worklist!$A$2:$A$434,A7,Worklist!$L$2:$L$434,"") -> 148 | D7: =COUNTIFS(Worklist!$A$2:$A$434,A7,Worklist!$M$2:$M$434,"") -> 157 | E7: =COUNTIFS(Worklist!$A$2:$A$434,A7,Worklist!$N$2:$N$434,"yes") -> 0
A8: 3 Active library | B8: =COUNTIF(Worklist!$A$2:$A$434,A8) -> 142 | C8: =COUNTIFS(Worklist!$A$2:$A$434,A8,Worklist!$L$2:$L$434,"") -> 129 | D8: =COUNTIFS(Worklist!$A$2:$A$434,A8,Worklist!$M$2:$M$434,"") -> 142 | E8: =COUNTIFS(Worklist!$A$2:$A$434,A8,Worklist!$N$2:$N$434,"yes") -> 0
A9: 4 Not yet (progression) | B9: =COUNTIF(Worklist!$A$2:$A$434,A9) -> 29 | C9: =COUNTIFS(Worklist!$A$2:$A$434,A9,Worklist!$L$2:$L$434,"") -> 14 | D9: =COUNTIFS(Worklist!$A$2:$A$434,A9,Worklist!$M$2:$M$434,"") -> 29 | E9: =COUNTIFS(Worklist!$A$2:$A$434,A9,Worklist!$N$2:$N$434,"yes") -> 0
A10: 5 Custom exercise | B10: =COUNTIF(Worklist!$A$2:$A$434,A10) -> 16 | C10: =COUNTIFS(Worklist!$A$2:$A$434,A10,Worklist!$L$2:$L$434,"") -> 15 | D10: =COUNTIFS(Worklist!$A$2:$A$434,A10,Worklist!$M$2:$M$434,"") -> 16 | E10: =COUNTIFS(Worklist!$A$2:$A$434,A10,Worklist!$N$2:$N$434,"yes") -> 0
A11: 6 Batch 2 (not added yet) | B11: =COUNTIF(Worklist!$A$2:$A$434,A11) -> 24 | C11: =COUNTIFS(Worklist!$A$2:$A$434,A11,Worklist!$L$2:$L$434,"") -> 24 | D11: =COUNTIFS(Worklist!$A$2:$A$434,A11,Worklist!$M$2:$M$434,"") -> 24 | E11: =COUNTIFS(Worklist!$A$2:$A$434,A11,Worklist!$N$2:$N$434,"yes") -> 0
A12: Total | B12: =SUM(B6:B11) -> 433 | C12: =SUM(C6:C11) -> 333 | D12: =SUM(D6:D11) -> 371 | E12: =SUM(E6:E11) -> 62

Sheet Pilot review
A1: ID | B1: Name | C1: Video | D1: Channel | E1: Video title | F1: Confidence | G1: Concern | H1: Image | I1: Instructions (How) | J1: Your verdict (ok / swap / fix)
A2: fin-pushups | B2: Fin push-ups | C2: https://www.youtube.com/watch?v=FZvvs9rx4gs | D2: Kimmo | E2: Wrist push-ups & fin push-ups. | F2: low | G2: Niche; small channel | H2: YouTube thumbnail | I2: 1. Kneel and place the backs of the wrists on the floor, fingers pointing back. 2. Hands wide enough that forearms stay vertical at the bottom. 3. Start on the knees; lower slowly. 4. Press back up without letting the wrists roll. 5. Progress to full push-ups when comfortable. Keep volume low.
A3: neck-work | B3: Neck flexion / extension / lateral | C3: https://www.youtube.com/watch?v=6k9VQNN8B5U | D3: TrackActive | E3: Neck flexion and extension | F3: low | G3: Flexion/extension only, no lateral | H3: YouTube thumbnail | I3: 1. Sit or stand tall, shoulders relaxed. 2. Flexion: nod the chin toward the chest, then return. 3. Extension: look up and back slowly, then return. 4. Lateral: tilt the ear toward the shoulder on each side. 5. Add light hand or band resistance only once each direction moves pain-free. Slow reps.
A4: uphill-sprints | B4: Uphill sprint repeats | C4: https://www.youtube.com/watch?v=VzHQUh5jzsI | D4: TaylorMade Coaching & Events | E4: Hill Sprints Tutorial | F4: low | G4: Small channel | H4: YouTube thumbnail | I4: 1. Find a steep hill with 10–15 seconds of running on it. 2. Warm up well: easy jog, drills, a couple of strides. 3. Sprint up at near-max effort: lean from the ankles, drive the knees and arms. 4. Walk back down slowly. 5. Rest fully (2–3 minutes) before the next rep.
A5: band-pull-aparts | B5: Band pull-aparts | C5: https://www.youtube.com/watch?v=KLb758dtKwU | D5: The Chiropractic Biomechanic | E5: BAND PULL-APARTS | Build Shoulder Strength & Protect Your Rotator Cuff | F5: medium | H5: https://raw.githubusercontent.com/yuhonas/free-exercise-db/main/exercises/Band_Pull_Apart/0.jpg | I5: 1. Hold a light band at shoulder height, arms straight, hands shoulder-width. 2. Keep the ribs down; don't arch. 3. Pull the band apart by squeezing the shoulder blades together. 4. Bring the band to the chest, arms still straight. 5. Return slowly, keeping tension on the band.
A6: box-jump | B6: Box jump | C6: https://www.youtube.com/watch?v=G-bxQY57mKc | D6: Runna | E6: Box Jump Tutorial - Proper Form and Technique | F6: medium | H6: https://raw.githubusercontent.com/yuhonas/free-exercise-db/main/exercises/Front_Box_Jump/1.jpg | I6: 1. Stand about a foot from the box, feet hip-width. 2. Swing the arms back and dip into a quarter squat. 3. Jump, driving the arms up, and land softly on the whole foot. 4. Land in a half squat with knees over toes, then stand up tall. 5. Step down, don't jump down. Reset fully between reps.
A7: broad-jump | B7: Broad jump | C7: https://www.youtube.com/watch?v=dVgtvAXeBQw | D7: Athletics Coach | E7: The Fundamentals - Standing Long Jump | F7: medium | H7: YouTube thumbnail | I7: 1. Stand with feet hip-width, toes behind a line. 2. Swing the arms back and load the hips. 3. Explode forward, swinging the arms through. 4. Pull the knees up and reach the feet out to land. 5. Stick the landing with bent knees. Measure, walk back, reset.
A8: cable-row | B8: Seated cable row | C8: https://www.youtube.com/watch?v=OeLb503NZHk | D8: The Healthy Habit | E8: Seated Cable Row Tutorial: Build a Strong Back with Proper Form | F8: medium | H8: https://raw.githubusercontent.com/yuhonas/free-exercise-db/main/exercises/Seated_Cable_Rows/0.jpg | I8: 1. Sit tall, feet on the platform, knees slightly bent. 2. Grab the handle with arms straight, shoulders reaching forward. 3. Pull the shoulder blades back first, then the elbows past the torso. 4. Touch the handle to the lower ribs without leaning back. 5. Return slowly until the arms are straight and the shoulders reach forward.
A9: dorsal-pushups | B9: Dorsal push-ups | C9: https://www.youtube.com/watch?v=oSkF3CCExnY | D9: GymnasticBodies | E9: Learn How to Increase Your Flexibility - Dorsal Pushups | F9: medium | H9: YouTube thumbnail | I9: 1. Kneel and put the backs of the hands on the floor, arms turned in (pinkies pointing back or in). 2. Keep the load light: start on the knees. 3. Lower a few centimetres, then press back up. 4. Stop well short of pain in the wrist. 5. Build range and reps slowly over weeks.
A10: ext-rotation-bands | B10: External rotation — bands | C10: https://www.youtube.com/watch?v=4HqMXMn3FBk | D10: Lift With Michelle | E10: Band External Rotation Exercise | Form Tutorial For Rotator Cuff | F10: medium | H10: https://raw.githubusercontent.com/yuhonas/free-exercise-db/main/exercises/External_Rotation_with_Band/1.jpg | I10: 1. Anchor the band at elbow height. Stand side-on to it. 2. Elbow bent at 90°, tucked against your side (a rolled towel helps). 3. Start with the forearm across the belly. 4. Rotate the forearm out, away from the body, keeping the elbow pinned. 5. Return slowly. Do both arms.
A11: eye-cars | B11: Eye CARs | C11: https://www.youtube.com/watch?v=dfPY10zCZxQ | D11: CreativeLive | E11: Eye Drills to Improve Vision with Eric Cobb | F11: medium | G11: General Z-Health eye drills, not circles only | H11: YouTube thumbnail | I11: 1. Sit or stand tall, head still. Look straight ahead. 2. Move the eyes up as far as they go without strain. 3. Trace the largest slow circle you can: up, out to the side, down, across, back up. 4. Keep the head and face relaxed; only the eyes move. 5. Do 3 slow circles each direction, then close the eyes for a few breaths.
A12: farmers-walk | B12: Farmer's walk | C12: https://www.youtube.com/watch?v=NH7Xv-7NQNQ | D12: Buff Dudes Workouts | E12: How To Perform Farmer Walks Exercise Tutorial | F12: medium | H12: https://raw.githubusercontent.com/yuhonas/free-exercise-db/main/exercises/Farmers_Walk/1.jpg | I12: 1. Deadlift the weights up with a flat back. 2. Stand tall, shoulders down and back, weights at your sides. 3. Brace the core. 4. Walk with short, quick steps, keeping the torso still. 5. Walk the set distance, then set the weights down with a flat back.
A13: hamstring-pnf | B13: Hamstring — PNF | C13: https://www.youtube.com/watch?v=xjWfi4S6yOI | D13: Saif Haquz | E13: PNF / Contract-Relax Stretching Technique For Hamstring | F13: medium | H13: YouTube thumbnail | I13: 1. Lie on your back and lift one straight leg; hold it with a strap or your hands. 2. Take it to a mild stretch. 3. Contract: push the leg down into the strap at about 30% effort for 5–6 seconds. 4. Relax, then pull the leg a little further on the exhale. 5. Repeat 3–4 rounds per side.
A14: hip-thrust | B14: Hip thrust / glute bridge | C14: https://www.youtube.com/watch?v=mJObkwsEkWs | D14: Colossus Fitness | E14: How to PROPERLY Do Barbell Hip Thrusts (Perfect Form) | F14: medium | H14: https://raw.githubusercontent.com/yuhonas/free-exercise-db/main/exercises/Barbell_Hip_Thrust/0.jpg | I14: 1. Sit with the upper back against a bench, bar padded over the hips. 2. Feet flat, about hip-width, shins vertical at the top. 3. Tuck the chin and ribs; tilt the pelvis back. 4. Drive through the heels until hips are fully extended. 5. Squeeze the glutes for 1–2 seconds, then lower under control.
A15: incline-bench | B15: Incline bench press | C15: https://www.youtube.com/watch?v=5kyLUGVq_pk | D15: Colossus Fitness | E15: How to PROPERLY Incline Barbell Bench Press (FIX YOUR FORM NOW) | F15: medium | H15: https://raw.githubusercontent.com/yuhonas/free-exercise-db/main/exercises/Barbell_Incline_Bench_Press_-_Medium_Grip/0.jpg | I15: 1. Bench at about 30°. Eyes under the bar, feet planted. 2. Squeeze the shoulder blades back and down; keep a slight arch. 3. Grip just outside shoulder-width. Unrack over the upper chest. 4. Lower with control to the upper chest, elbows about 45–60° from the body. 5. Press up and slightly back to lockout over the shoulders.
A16: interval-run | B16: Interval run | C16: https://www.youtube.com/watch?v=3r0Kd3G4kek | D16: VO2 Max Lab | E16: Norwegian 4x4 Interval Training | Increase VO2 max and Endurance! | F16: medium | H16: YouTube thumbnail | I16: 1. Warm up for 10–15 minutes of easy running plus a few strides. 2. Run 4 minutes hard, reaching 90–95% of max heart rate. 3. Recover 3 minutes with easy jogging. 4. Repeat for 4 rounds. 5. Cool down for 10 minutes easy.
A17: lateral-raise | B17: Lateral raise | C17: https://www.youtube.com/watch?v=pgrWjBfaFe8 | D17: Colossus Fitness | E17: How to PROPERLY Dumbbell Lateral Raise For Bigger Shoulders (FIX THIS!) | F17: medium | H17: https://raw.githubusercontent.com/yuhonas/free-exercise-db/main/exercises/Side_Lateral_Raise/1.jpg | I17: 1. Stand tall, dumbbells at your sides, slight bend in the elbows. 2. Lean slightly forward from the hips. 3. Raise the arms out to the side, leading with the elbows. 4. Stop at shoulder height, hands no higher than elbows. 5. Lower slowly over 2–3 seconds.
A18: middle-splits | B18: Middle splits progression | C18: https://www.youtube.com/watch?v=4RkHIxk-K8Q | D18: Movesmethod | E18: Learn Middle Splits In 4 Months! | F18: medium | G18: General progression, not blocks/slider specific | H18: YouTube thumbnail | I18: 1. Stand with feet wide, hands on blocks or the floor. 2. Slide the feet out slowly (on a sliding surface if you have one). 3. Keep the toes pointed up or forward and the knees straight. 4. Stop at a strong but tolerable stretch; hold and breathe. 5. Push down with the inner thighs to come back up.
A19: overhead-press | B19: Overhead press | C19: https://www.youtube.com/watch?v=KEAS2bypjFg | D19: Colossus Fitness | E19: How to PROPERLY Perform the Overhead Press (OHP EXPLAINED!) | F19: medium | H19: https://raw.githubusercontent.com/yuhonas/free-exercise-db/main/exercises/Standing_Military_Press/1.jpg | I19: 1. Bar on the front of the shoulders, grip just outside shoulder-width, elbows slightly forward. 2. Squeeze glutes and brace; ribs down. 3. Press straight up, moving the head back out of the way. 4. At the top, push the head through so the bar is over the mid-foot and ears are between the arms. 5. Lower under control to the shoulders.
A20: peripheral-tracking | B20: Peripheral tracking | C20: https://www.youtube.com/watch?v=RhdUV4F_ybM | D20: Neurobuff | E20: Peripheral Vision Training - Improve Situational Awareness | F20: medium | H20: YouTube thumbnail | I20: 1. Pick a fixed point straight ahead and keep your eyes on it the whole time. 2. Hold a finger or pen at arm's length in front of you. 3. Move it slowly out to the side and around the edge of your vision. 4. Notice how far out you can still sense its movement without looking at it. 5. Work both sides, above and below. 1–2 minutes.
A21: ring-dip | B21: Ring dip | C21: https://www.youtube.com/watch?v=DY4wvmSDP0g | D21: Leon Thorley | E21: How To Ring Dip for Beginners - Perfect Form & Common Mistakes! | F21: medium | H21: YouTube thumbnail | I21: 1. Start in the ring support: arms locked, rings by your sides. 2. Lower slowly, elbows tracking back, rings staying close to the body. 3. Go down until the shoulders are just below the elbows. 4. Keep the rings from drifting out. 5. Press up and turn the rings out at the top.
A22: ring-hold-support | B22: Ring hold — support | C22: https://www.youtube.com/watch?v=6IWGetY9qLw | D22: TotalHumanOptimization | E22: The Ring Support Hold | All Variations Step by Step | F22: medium | H22: YouTube thumbnail | I22: 1. Rings at about hip height. Jump or press into support. 2. Arms locked, shoulders pushed down away from the ears. 3. Turn the rings out slightly so the palms face forward. 4. Body straight, legs together, rings against the sides. 5. Hold with minimal shaking. Practise with a false grip (wrist over the ring) in some sets.
A23: toes-to-bar | B23: Toes to bar | C23: https://www.youtube.com/watch?v=j2r4iMy8Hb0 | D23: The Strength Institute | E23: Toes To Bar (Strict) - Tutorial | F23: medium | H23: YouTube thumbnail | I23: 1. Hang from the bar, arms straight, shoulders engaged. 2. Brace the core and tilt the pelvis back slightly. 3. Keeping legs as straight as you can, raise the feet toward the bar. 4. Touch the bar with the toes without swinging. 5. Lower slowly to the hang and kill any swing before the next rep.
A24: ball-eye-patched | B24: Ping pong ball vs wall — eye patched | C24: https://www.youtube.com/watch?v=JNHxkeRmMws | D24: YouGoProBaseball | E24: Catching Drills - One Eye Vision Drill for Catching | F24: high | H24: YouTube thumbnail | I24: 1. Cover one eye with a patch or your hand. 2. Stand 1–2 m from a solid wall with a ping pong or tennis ball. 3. Throw the ball at the wall and catch it with the same hand. 4. Keep a steady rhythm; move closer or throw faster to progress. 5. Do the same amount of time with the other eye covered, then switch hands.
A25: body-scan | B25: Body scan | C25: https://www.youtube.com/watch?v=MHc-rbfSbwk | D25: Fostering Resilience | E25: 10 Minute Guided Body Scan Meditation | F25: high | H25: YouTube thumbnail | I25: 1. Lie on your back or sit, eyes closed. Take a few slow breaths. 2. Bring attention to the toes of one foot. Notice what is there without changing it. 3. Move attention slowly up: foot, ankle, calf, knee, thigh, hip. Then the other leg. 4. Continue through pelvis, belly, chest, back, hands, arms, shoulders, neck, face and scalp. 5. Finish by sensing the whole body at once for a few breaths.
A26: breathing-478 | B26: 4-7-8 breathing | C26: https://www.youtube.com/watch?v=YRPh_GaiL8s | D26: Andrew Weil, M.D. | E26: How To Perform the 4-7-8 Breathing Exercise | Andrew Weil, M.D. | F26: high | H26: YouTube thumbnail | I26: 1. Sit or lie comfortably. Rest the tip of the tongue just behind the upper front teeth. 2. Exhale fully through the mouth with a soft whoosh. 3. Close the mouth and inhale quietly through the nose for 4 counts. 4. Hold the breath for 7 counts. 5. Exhale through the mouth for 8 counts. That is one breath; repeat for 4 breaths to start.
A27: couch-stretch | B27: Hip flexor / couch stretch | C27: https://www.youtube.com/watch?v=WKo4APrwfXQ | D27: Flow Motion Fitness | E27: Couch Stretch Progressions: Beginner To Advanced | F27: high | H27: YouTube thumbnail | I27: 1. Kneel with one knee at the base of a wall or couch, shin up against it. 2. Put the other foot forward in a lunge. 3. Squeeze the glute of the back leg and tuck the pelvis. 4. Slowly bring the torso upright. 5. Hold 1–2 minutes each side, breathing slowly.
A28: dead-hang | B28: Dead hang | C28: https://www.youtube.com/watch?v=jBZCzK9zlxk | D28: Dr. Allan Bacon | E28: Dead Hang Tutorial | F28: high | H28: YouTube thumbnail | I28: 1. Grip the bar shoulder-width, full grip with the thumbs. 2. Let the body hang, arms straight. 3. Relax the shoulders up toward the ears and let the spine lengthen. 4. Keep the legs quiet and breathe slowly. 5. Step down before the grip fails.
A29: deadlift | B29: Deadlift | C29: https://www.youtube.com/watch?v=XxWcirHIwVo | D29: Jeremy Ethier | E29: How to PROPERLY Deadlift for Growth (5 Easy Steps) | F29: high | H29: https://raw.githubusercontent.com/yuhonas/free-exercise-db/main/exercises/Barbell_Deadlift/0.jpg | I29: 1. Bar over mid-foot, feet hip-width. Grip just outside the legs. 2. Hips down until the shins touch the bar; chest up, back flat. 3. Take the slack out of the bar, brace hard. 4. Push the floor away, bar dragging up the legs. 5. Lock out with hips and knees together. Lower by hinging the hips back first.
A30: face-pulls | B30: Face pulls | C30: https://www.youtube.com/watch?v=ljgqer1ZpXg | D30: ATHLEAN-X | E30: STOP F*cking Up Face Pulls (PROPER FORM!) | F30: high | H30: https://raw.githubusercontent.com/yuhonas/free-exercise-db/main/exercises/Face_Pull/0.jpg | I30: 1. Rope at upper-chest or face height. Grip with thumbs toward you. 2. Step back until the arms are straight and the cable is taut. 3. Pull the rope toward the face, elbows high and wide. 4. Finish by rotating the hands back so they end beside the ears. 5. Pause, then return slowly.
... A62: yoga-seated-forward-fold | B62: Seated forward fold | C62: https://www.youtube.com/watch?v=g7Uhp5tphAs | D62: Yoga With Adriene | E62: Forward Fold Yoga Pose - Yoga With Adriene | F62: high | H62: YouTube thumbnail | I62: 1. Sit with legs straight in front, feet flexed. 2. Sit up tall; a cushion under the hips helps. 3. Hinge forward from the hips, keeping the back long. 4. Reach toward the feet without pulling the back into a round. 5. Hold and breathe; soften on each exhale.
A63: active-hang | B63: Active hang | C63: https://www.youtube.com/watch?v=HoE-C85ZlCE | F63: existing | H63: YouTube thumbnail | I63: 1. Start in a dead hang, arms straight. 2. Pull the shoulder blades down away from the ears without bending the elbows. 3. The body rises a few centimetres. 4. Hold for 3 seconds. 5. Relax back to a dead hang for 1 second. Repeat.
A64: easy-run | B64: Easy run | F64: skipped (cardio) | H64: none | I64: 1. Warm up with a few minutes of walking or very easy jogging. 2. Run at a pace you can hold a conversation at. 3. Breathe through the nose if you can. 4. Keep steps short and relaxed. 5. Cool down with a few minutes of walking.
A65: walking | B65: Walking / hiking | F65: skipped (cardio) | H65: none | I65: 1. Walk at a relaxed pace. 2. No targets. Just move.
A66: z2-cycling | B66: Zone 2 indoor cycling | F66: skipped (cardio) | H66: none | I66: 1. Set up the bike: slight knee bend at the bottom of the pedal stroke. 2. Warm up for 5 minutes easy. 3. Ride at zone 2 heart rate, where nose breathing is comfortable. 4. Keep the cadence smooth, around 80–90 rpm. 5. Hold for the planned time. Cool down 5 minutes.

Sheet Worklist
A1: Tier | B1: ID | C1: Name | D1: Category | E1: State | F1: Why | G1: Video now | H1: Image now | I1: Note | J1: YouTube search | K1: Image search | L1: Video URL (fill) | M1: Image/GIF URL (fill) | N1: Done
A2: 1 In plan / logged | B2: hollow-body-hold | C2: Hollow body hold | D2: Body Movement / Gymnastics Conditioning | E2: active | F2: month plan, logged, rotation | G2: search placeholder | H2: NONE | J2: Search | K2: Search | L2: https://www.youtube.com/watch?v=HAfUt2Cco74 | M2: YouTube thumbnail (auto) | N2: =IF(AND(L2<>"",M2<>""),"yes",IF(OR(L2<>"",M2<>""),"partial","no")) -> yes
A3: 1 In plan / logged | B3: dead-hang | C3: Dead hang | D3: Body Movement / Hanging | E3: active | F3: month plan, logged, rotation | G3: search placeholder | H3: NONE | J3: Search | K3: Search | L3: https://www.youtube.com/watch?v=jBZCzK9zlxk | M3: YouTube thumbnail (auto) | N3: =IF(AND(L3<>"",M3<>""),"yes",IF(OR(L3<>"",M3<>""),"partial","no")) -> yes
A4: 1 In plan / logged | B4: z2-cycling | C4: Zone 2 indoor cycling | D4: Cardio / Cycling | E4: active | F4: month plan, logged | G4: search placeholder | H4: NONE | I4: optional (cardio/breath) | J4: Search | K4: Search | N4: =IF(AND(L4<>"",M4<>""),"yes",IF(OR(L4<>"",M4<>""),"partial","no")) -> no
A5: 1 In plan / logged | B5: easy-run | C5: Easy run | D5: Cardio / Run | E5: active | F5: month plan, logged | G5: search placeholder | H5: NONE | I5: optional (cardio/breath) | J5: Search | K5: Search | N5: =IF(AND(L5<>"",M5<>""),"yes",IF(OR(L5<>"",M5<>""),"partial","no")) -> no
A6: 1 In plan / logged | B6: interval-run | C6: Interval run | D6: Cardio / Run | E6: active | F6: month plan, logged | G6: search placeholder | H6: NONE | I6: optional (cardio/breath) | J6: Search | K6: Search | L6: https://www.youtube.com/watch?v=3r0Kd3G4kek | M6: YouTube thumbnail (auto) | N6: =IF(AND(L6<>"",M6<>""),"yes",IF(OR(L6<>"",M6<>""),"partial","no")) -> yes
A7: 1 In plan / logged | B7: tempo-run | C7: Tempo run | D7: Cardio / Run | E7: active | F7: month plan | G7: search placeholder | H7: NONE | I7: optional (cardio/breath) | J7: Search | K7: Search | L7: https://www.youtube.com/watch?v=hDYp3U8b1nU | M7: YouTube thumbnail (auto) | N7: =IF(AND(L7<>"",M7<>""),"yes",IF(OR(L7<>"",M7<>""),"partial","no")) -> yes
A8: 1 In plan / logged | B8: walking | C8: Walking / hiking | D8: Cardio / Walk | E8: active | F8: month plan, logged, rotation | G8: NONE | H8: NONE | I8: optional (cardio/breath) | J8: Search | K8: Search | N8: =IF(AND(L8<>"",M8<>""),"yes",IF(OR(L8<>"",M8<>""),"partial","no")) -> no
A9: 1 In plan / logged | B9: hamstring-hang | C9: Hamstring — passive hang | D9: Flexibility / Hamstring | E9: active | F9: logged, rotation | G9: search placeholder | H9: NONE | J9: Search | K9: Search | L9: https://www.youtube.com/watch?v=2W7Dhf6n5aM | M9: YouTube thumbnail (auto) | N9: =IF(AND(L9<>"",M9<>""),"yes",IF(OR(L9<>"",M9<>""),"partial","no")) -> yes
A10: 1 In plan / logged | B10: hamstring-pike | C10: Hamstring — standing pike | D10: Flexibility / Hamstring | E10: active | F10: logged, rotation | G10: search placeholder | H10: NONE | J10: Search | K10: Search | L10: https://www.youtube.com/watch?v=B6--yoHH_Mw | M10: YouTube thumbnail (auto) | N10: =IF(AND(L10<>"",M10<>""),"yes",IF(OR(L10<>"",M10<>""),"partial","no")) -> yes
A11: 1 In plan / logged | B11: hamstring-pnf | C11: Hamstring — PNF | D11: Flexibility / Hamstring | E11: active | F11: logged, rotation | G11: search placeholder | H11: NONE | J11: Search | K11: Search | L11: https://www.youtube.com/watch?v=xjWfi4S6yOI | M11: YouTube thumbnail (auto) | N11: =IF(AND(L11<>"",M11<>""),"yes",IF(OR(L11<>"",M11<>""),"partial","no")) -> yes
A12: 1 In plan / logged | B12: couch-stretch | C12: Hip flexor / couch stretch | D12: Flexibility / Hip | E12: active | F12: logged, rotation | G12: search placeholder | H12: NONE | J12: Search | K12: Search | L12: https://www.youtube.com/watch?v=WKo4APrwfXQ | M12: YouTube thumbnail (auto) | N12: =IF(AND(L12<>"",M12<>""),"yes",IF(OR(L12<>"",M12<>""),"partial","no")) -> yes
A13: 1 In plan / logged | B13: hip-90-90-stretch | C13: 90/90 hip stretch | D13: Flexibility / Hip | E13: active | F13: logged, rotation | G13: search placeholder | H13: NONE | J13: Search | K13: Search | L13: https://www.youtube.com/watch?v=t4Zz6-aG8Iw | M13: YouTube thumbnail (auto) | N13: =IF(AND(L13<>"",M13<>""),"yes",IF(OR(L13<>"",M13<>""),"partial","no")) -> yes
A14: 1 In plan / logged | B14: runners-lunge-stretch | C14: Runner's lunge stretch | D14: Flexibility / Hip | E14: active | F14: logged, rotation | G14: search placeholder | H14: NONE | J14: Search | K14: Search | L14: https://www.youtube.com/watch?v=iZ1eZBY4fwM | M14: https://raw.githubusercontent.com/yuhonas/free-exercise-db/main/exercises/Kneeling_Hip_Flexor/0.jpg | N14: =IF(AND(L14<>"",M14<>""),"yes",IF(OR(L14<>"",M14<>""),"partial","no")) -> yes
A15: 1 In plan / logged | B15: half-split-stretch | C15: Half split stretch | D15: Flexibility / Hip | E15: active | F15: logged, rotation | G15: search placeholder | H15: NONE | J15: Search | K15: Search | L15: https://www.youtube.com/watch?v=h_wtmUMu0MU | M15: YouTube thumbnail (auto) | N15: =IF(AND(L15<>"",M15<>""),"yes",IF(OR(L15<>"",M15<>""),"partial","no")) -> yes
A16: 1 In plan / logged | B16: foam-rolling | C16: Foam rolling — general | D16: Flexibility / Self-Massage | E16: active | F16: logged | G16: search placeholder | H16: NONE | J16: Search | K16: Search | L16: https://www.youtube.com/watch?v=Oc6gHIS7Qos | M16: YouTube thumbnail (auto) | N16: =IF(AND(L16<>"",M16<>""),"yes",IF(OR(L16<>"",M16<>""),"partial","no")) -> yes
A17: 1 In plan / logged | B17: pancake | C17: Pancake / straddle floor | D17: Flexibility / Splits | E17: active | F17: month plan, rotation | G17: search placeholder | H17: NONE | J17: Search | K17: Search | L17: https://www.youtube.com/watch?v=CHRUb43S6RM | M17: https://raw.githubusercontent.com/yuhonas/free-exercise-db/main/exercises/The_Straddle/0.jpg | N17: =IF(AND(L17<>"",M17<>""),"yes",IF(OR(L17<>"",M17<>""),"partial","no")) -> yes
A18: 1 In plan / logged | B18: middle-splits | C18: Middle splits progression | D18: Flexibility / Splits | E18: active | F18: month plan | G18: search placeholder | H18: NONE | J18: Search | K18: Search | L18: https://www.youtube.com/watch?v=4RkHIxk-K8Q | M18: YouTube thumbnail (auto) | N18: =IF(AND(L18<>"",M18<>""),"yes",IF(OR(L18<>"",M18<>""),"partial","no")) -> yes
A19: 1 In plan / logged | B19: hip-thrust | C19: Hip thrust / glute bridge | D19: Gym / Accessory | E19: active | F19: logged, rotation | G19: search placeholder | H19: NONE | J19: Search | K19: Search | L19: https://www.youtube.com/watch?v=mJObkwsEkWs | M19: https://raw.githubusercontent.com/yuhonas/free-exercise-db/main/exercises/Barbell_Hip_Thrust/0.jpg | N19: =IF(AND(L19<>"",M19<>""),"yes",IF(OR(L19<>"",M19<>""),"partial","no")) -> yes
A20: 1 In plan / logged | B20: face-pulls | C20: Face pulls | D20: Gym / Accessory | E20: active | F20: logged, rotation | G20: search placeholder | H20: NONE | J20: Search | K20: Search | L20: https://www.youtube.com/watch?v=ljgqer1ZpXg | M20: https://raw.githubusercontent.com/yuhonas/free-exercise-db/main/exercises/Face_Pull/0.jpg | N20: =IF(AND(L20<>"",M20<>""),"yes",IF(OR(L20<>"",M20<>""),"partial","no")) -> yes
... A40: 1 In plan / logged | B40: plank | C40: Plank | D40: Gym / Strength B | E40: active | F40: month plan, logged | G40: search placeholder | H40: NONE | J40: Search | K40: Search | L40: https://www.youtube.com/watch?v=A2b2EmIg0dA | M40: https://raw.githubusercontent.com/yuhonas/free-exercise-db/main/exercises/Plank/1.jpg | N40: =IF(AND(L40<>"",M40<>""),"yes",IF(OR(L40<>"",M40<>""),"partial","no")) -> yes
A41: 1 In plan / logged | B41: body-scan | C41: Body scan | D41: Meditation / Awareness | E41: active | F41: logged, rotation | G41: search placeholder | H41: NONE | I41: optional (cardio/breath) | J41: Search | K41: Search | L41: https://www.youtube.com/watch?v=MHc-rbfSbwk | M41: YouTube thumbnail (auto) | N41: =IF(AND(L41<>"",M41<>""),"yes",IF(OR(L41<>"",M41<>""),"partial","no")) -> yes
A42: 1 In plan / logged | B42: breathing-478 | C42: 4-7-8 breathing | D42: Meditation / Breathwork | E42: active | F42: logged | G42: search placeholder | H42: NONE | I42: optional (cardio/breath) | J42: Search | K42: Search | L42: https://www.youtube.com/watch?v=YRPh_GaiL8s | M42: YouTube thumbnail (auto) | N42: =IF(AND(L42<>"",M42<>""),"yes",IF(OR(L42<>"",M42<>""),"partial","no")) -> yes
A43: 1 In plan / logged | B43: juggling-cascade | C43: Juggling — 3 ball cascade | D43: Object Manipulation / Juggling | E43: active | F43: logged | G43: search placeholder | H43: NONE | J43: Search | K43: Search | L43: https://www.youtube.com/watch?v=SHYDbOLrU1w | M43: YouTube thumbnail (auto) | N43: =IF(AND(L43<>"",M43<>""),"yes",IF(OR(L43<>"",M43<>""),"partial","no")) -> yes
A44: 1 In plan / logged | B44: juggling-variations | C44: Juggling — variations / tricks | D44: Object Manipulation / Juggling | E44: active | F44: logged | G44: search placeholder | H44: NONE | J44: Search | K44: Search | L44: https://www.youtube.com/watch?v=SSbNtVfMdgM | M44: YouTube thumbnail (auto) | N44: =IF(AND(L44<>"",M44<>""),"yes",IF(OR(L44<>"",M44<>""),"partial","no")) -> yes
A45: 1 In plan / logged | B45: juggling-columns | C45: Juggling — columns | D45: Object Manipulation / Juggling | E45: active | F45: logged | G45: search placeholder | H45: NONE | J45: Search | K45: Search | L45: https://www.youtube.com/watch?v=nkAMDSNXCxY | M45: YouTube thumbnail (auto) | N45: =IF(AND(L45<>"",M45<>""),"yes",IF(OR(L45<>"",M45<>""),"partial","no")) -> yes
A46: 1 In plan / logged | B46: juggling-reverse-cascade | C46: Juggling — reverse cascade | D46: Object Manipulation / Juggling | E46: active | F46: logged | G46: search placeholder | H46: NONE | J46: Search | K46: Search | L46: https://www.youtube.com/watch?v=rDeneW2EoxQ | M46: YouTube thumbnail (auto) | N46: =IF(AND(L46<>"",M46<>""),"yes",IF(OR(L46<>"",M46<>""),"partial","no")) -> yes
A47: 1 In plan / logged | B47: juggling-half-shower | C47: Juggling — half shower | D47: Object Manipulation / Juggling | E47: active | F47: logged | G47: search placeholder | H47: NONE | J47: Search | K47: Search | L47: https://www.youtube.com/watch?v=Mf04OllYlOM | M47: YouTube thumbnail (auto) | N47: =IF(AND(L47<>"",M47<>""),"yes",IF(OR(L47<>"",M47<>""),"partial","no")) -> yes
A48: 1 In plan / logged | B48: saccade-chart | C48: Saccadic jumps - two targets | D48: Object Manipulation / Reaction | E48: active | F48: logged, rotation | G48: search placeholder | H48: NONE | J48: Search | K48: Search | L48: https://www.youtube.com/watch?v=z-BH_95_f-w | M48: YouTube thumbnail (auto) | N48: =IF(AND(L48<>"",M48<>""),"yes",IF(OR(L48<>"",M48<>""),"partial","no")) -> yes
A49: 1 In plan / logged | B49: ball-eye-patched | C49: Ping pong ball vs wall — eye patched | D49: Object Manipulation / Tennis Ball | E49: active | F49: logged, rotation | G49: search placeholder | H49: NONE | J49: Search | K49: Search | L49: https://www.youtube.com/watch?v=JNHxkeRmMws | M49: YouTube thumbnail (auto) | N49: =IF(AND(L49<>"",M49<>""),"yes",IF(OR(L49<>"",M49<>""),"partial","no")) -> yes
A50: 1 In plan / logged | B50: broad-jump | C50: Broad jump | D50: Power / Jumps | E50: active | F50: month plan | G50: search placeholder | H50: NONE | J50: Search | K50: Search | L50: https://www.youtube.com/watch?v=dVgtvAXeBQw | M50: YouTube thumbnail (auto) | N50: =IF(AND(L50<>"",M50<>""),"yes",IF(OR(L50<>"",M50<>""),"partial","no")) -> yes
A51: 1 In plan / logged | B51: uphill-sprints | C51: Uphill sprint repeats | D51: Power / Sprint | E51: active | F51: month plan | G51: search placeholder | H51: NONE | J51: Search | K51: Search | L51: https://www.youtube.com/watch?v=VzHQUh5jzsI | M51: YouTube thumbnail (auto) | N51: =IF(AND(L51<>"",M51<>""),"yes",IF(OR(L51<>"",M51<>""),"partial","no")) -> yes
A52: 1 In plan / logged | B52: med-ball-slams | C52: Medicine ball slams | D52: Power / Throws | E52: active | F52: month plan | G52: search placeholder | H52: NONE | J52: Search | K52: Search | L52: https://www.youtube.com/watch?v=lsMGmkvzFsE | M52: https://raw.githubusercontent.com/yuhonas/free-exercise-db/main/exercises/Overhead_Slam/1.jpg | N52: =IF(AND(L52<>"",M52<>""),"yes",IF(OR(L52<>"",M52<>""),"partial","no")) -> yes
A53: 1 In plan / logged | B53: ring-hold-support | C53: Ring hold — support | D53: Rings / Holds | E53: active | F53: logged, rotation | G53: search placeholder | H53: NONE | J53: Search | K53: Search | L53: https://www.youtube.com/watch?v=6IWGetY9qLw | M53: YouTube thumbnail (auto) | N53: =IF(AND(L53<>"",M53<>""),"yes",IF(OR(L53<>"",M53<>""),"partial","no")) -> yes
A54: 1 In plan / logged | B54: german-hang | C54: Ring hold — German hang | D54: Rings / Holds | E54: active | F54: logged, rotation | G54: search placeholder | H54: NONE | J54: Search | K54: Search | L54: https://www.youtube.com/watch?v=5KaDOUeMY98 | M54: YouTube thumbnail (auto) | N54: =IF(AND(L54<>"",M54<>""),"yes",IF(OR(L54<>"",M54<>""),"partial","no")) -> yes
... A66: 1 In plan / logged | B66: active-hang | C66: Active hang | D66: Body Movement / Hanging | E66: active | F66: logged, rotation | G66: has video | H66: NONE | J66: Search | K66: Search | L66: https://www.youtube.com/watch?v=HoE-C85ZlCE | M66: YouTube thumbnail (auto) | N66: =IF(AND(L66<>"",M66<>""),"yes",IF(OR(L66<>"",M66<>""),"partial","no")) -> yes
A67: 2 Complementary rotation | B67: glute-bridge-bw | C67: Glute bridge (bodyweight) | D67: Body Movement / Activation | E67: active | F67: rotation | G67: search placeholder | H67: NONE | J67: Search | K67: Search | N67: =IF(AND(L67<>"",M67<>""),"yes",IF(OR(L67<>"",M67<>""),"partial","no")) -> no
A68: 2 Complementary rotation | B68: banded-lateral-walk | C68: Banded lateral walk | D68: Body Movement / Activation | E68: active | F68: rotation | G68: search placeholder | H68: NONE | J68: Search | K68: Search | N68: =IF(AND(L68<>"",M68<>""),"yes",IF(OR(L68<>"",M68<>""),"partial","no")) -> no
A69: 2 Complementary rotation | B69: dead-bug | C69: Dead bug | D69: Body Movement / Activation | E69: active | F69: rotation | G69: search placeholder | H69: NONE | J69: Search | K69: Search | N69: =IF(AND(L69<>"",M69<>""),"yes",IF(OR(L69<>"",M69<>""),"partial","no")) -> no
A70: 2 Complementary rotation | B70: bird-dog | C70: Bird dog | D70: Body Movement / Activation | E70: active | F70: rotation | G70: search placeholder | H70: NONE | J70: Search | K70: Search | N70: =IF(AND(L70<>"",M70<>""),"yes",IF(OR(L70<>"",M70<>""),"partial","no")) -> no
...
